Workbook

Sheet 2025
A1: No | B1: Nomor Surat | C1: Nama Rombongan / Instansi | D1: NOPOL | E1: Tanggal Kunjungan | F1: Keperluan | G1: Jam Loading | H1: 226
A2: 1 | B2: 467 | C2: Ibu Dina Stikes | D2: 4 Mobil : B 2090 PIE , B 9784 LS, ELF 7503-06, (B. ) | E2: 45913 | F2: Loading Barang Ke Lapangan Timur Gajah | G2: 07,00 s/d 07,30 WIB. | H2: Dispensasi
A3: 2 | B3: 468 | C3: PT. Rentokil Indonesia | D3: 2 Mobil : B 9523 BXB, B 9174 BCR | E3: 45916 | F3: Loading Barang Ke Taman Satwa Anak Pendopo 1 & 4 | G3: 07,00 s/d 07,30 WIB.
A4: 3 | B4: 469 | C4: TK. Islam Daruttaqwa | D4: 1 Motor : B 5603 TMG | E4: 45917 | F4: Loading Barang Ke Taman Satwa Anak Pendopo 4 | G4: 07,00 s/d 07,30 WIB. | H4: https://docs.google.com/spreadsheets/d/1GIYP3gKlwKD1FjOm9J1bBxcXXS3yi7xxxQRVqMkhHXI/edit?gid=677168732#gid=677168732
A5: 4 | B5: 470 | C5: PT. OHP / Mayora | D5: 6 dewasa , 1 mobil | E5: 3 Hari , 5, 6, 7 September 2025 | G5: 07,00 s/d 07,30 WIB.
A6: 5 | B6: 471 | C6: GPIB PS. MINGGU | D6: 1 Mobil : B 1183 DFS | E6: 45921 | F6: Loading Barang Ke Lapangan ATM Informasi | G6: 07,00 s/d 07,30 WIB.
A7: 6 | B7: 472 | C7: MUHAJIR | D7: 1 Mobil B 9514 SRU | E7: 45917 | F7: Loading barang ke LAp Gajah Timur | G7: 07,00 s/d 07,30 WIB.
A8: 7 | B8: 473 | C8: RICO | D8: 1 Mobi R 1827 FP | E8: 45920 | F8: Loading barang ke Taman Satwa Anak Pendopo 1 | G8: 06,00 s/d 07,30 WIB.
A9: 8 | B9: 474 | C9: Miyarni | D9: 1 Mobil B 2161 FYA | E9: 45927 | F9: Loading barang ke Taman Satwa Anak Pendopo 4 | G9: 06,00 s/d 07,30 WIB.
A10: 9 | B10: 475 | C10: Paguyuban Haji Jagakarsa | D10: 1 Mobil B 1869 DKF | E10: 45920 | F10: Loading barang ke Taman Satwa Anak Pendopo 4 | G10: 06,00 s/d 07,30 WIB.
A11: 10 | B11: 476 | C11: Need's | D11: 8 Dewasa, 4 Mobil | E11: 4 Hari, 20,21, 27 dan 28 Sept 2025 | F11: Loading barang | G11: 06,00 s/d 07,30 WIB.
A12: 11 | B12: 477 | C12: BP. MADIO SUWITO GOMBONG | D12: 1 Mobil B 1165 EYR | E12: 45921 | F12: Loading barang LAP ATM 3 | G12: 06,00 s/d 07,30 WIB.
A13: 12 | B13: 478 | C13: Frosty Ice Cream | E13: 2 Hari 20, 21 September 2025 | G13: 06,00 s/d 07,30 WIB.
A14: 13 | B14: 479 | C14: adi limitless | D14: 3 mobil , F 1872 AAQ, B 2803 SIH, Lalamove | E14: 45920 | F14: loadiing barang aula serbaguna | G14: 07,00 s/d 07,30 WIB.
A15: 14 | B15: 480 | C15: Ashar Arsyad | D15: 1 mobil, B 1491 FYL | E15: 45921 | F15: loadiing barang aula TSA | G15: 07,00 s/d 07,30 WIB.
A16: 15 | B16: 481 | C16: GPIB Markus Septi | D16: 1 mobil, B1161 DKG | E16: 45922 | F16: loadiing barang lapaangan timur informasi | G16: 07,00 s/d 07,30 WIB.
A17: 16 | B17: 482 | C17: PDGI Jakarta Selatan | D17: 1 mobil, B 9240 WQO | E17: 45926 | F17: loading tenda | G17: 07,00 s/d 07,30 WIB.
A18: 17 | B18: 483 | C18: PDGI Jakarta Selatan | D18: 1 mobil, B 7562 JA | E18: 45927 | F18: Standby saat Hari H (Pemeriksaan Baksos) | G18: 07,00 s/d 07,30 WIB.
A19: 18 | C19: Momogi | D19: 4 Dewasa 1 Mobil | E19: 2 Hari, 27 dan 28 September 2025 | F19: loading barang | G19: 06,00 s/d 07,30 WIB.
A20: 19 | B20: 485 | C20: SHASI | D20: 1 Mobil B 2265 Box | E20: 45927 | F20: Loading Barang ke Pendopo 2 DI TSA | G20: 06,00 s/d 07,30 WIB.
A21: 20 | B21: 486 | C21: Pak jhony | D21: D 1751 ES dan B 1972 EYA | E21: 45927 | F21: Loadiing barang lapangan teras informasi dan LAP TIMUR INF 2 | G21: 06,00 s/d 07,30 WIB.
A22: 21 | B22: 487 | C22: PHD | D22: 2 Dewasa 2 motor | E22: 28 September 2025 dan 5 oktober 2025 | F22: Loading barang | G22: 06,00 s/d 07,30 WIB.
A23: 22 | B23: 488 | C23: Koedsi bpk budi | D23: 1 Mobil, B 2246 SIE | E23: 45928 | F23: Loading barang lapangan atm 4 | G23: 06,00 s/d 07,30 WIB.
A24: 23 | B24: 489 | C24: Arisan Vena | D24: 1 Mobil ( B 2636 UYX ) | E24: 45928 | F24: Loading Barang ke- TSA 2 | G24: 07,00 s/d 07,30 WIB.
A25: 24 | B25: 490 | C25: Gereja Pouk Citragrand Cibubur | D25: 1 Mobil ( B 1349 SZX ) | E25: 45928 | F25: Loading Barang ke- TSA 4 | G25: 07,00 s/d 07,30 WIB.
A26: 25 | B26: 491 | C26: Keluarga AE | D26: 1 Mobil ( B 2745 KMO ) | E26: 45928 | F26: Loading Barang ke- TSA 3 | G26: 07,00 s/d 07,30 WIB.
A27: 26 | B27: 492 | C27: SD Muhammadiyah jak pus | D27: 1 mobil B 1203 PFK | E27: 45930 | F27: Loading Barang ke- TSA 1 | G27: 07,00 s/d 07,30 WIB.
A28: 27 | B28: 493 | C28: PT. Sumber Karya Pakarindo | D28: 1 Mobil ( ), 1 Motor ( ), 4 Dewasa | E28: 4,5,11 dan 12 Pktober 2025 | F28: Loading Barang Promo | G28: 06,00 s/d 07,30 WIB.
A29: 28 | B29: 494 | C29: Call donat | D29: 1 Mobil ( ), 2 Motor ( ), 3 Dewasa | E29: 4,5,12,19,25,26 Oktober 2025 | F29: Loading Barang Promo | G29: 06,00 s/d 07,30 WIB.
A30: 29 | B30: 495 | C30: Need's Eskrim | D30: 1 mobil ( ) 2 dewasa | E30: 4,5,11,12 Oktober 2025 | F30: Loding Barang Promo | G30: 06,00 s/d 07,30 WIB.
A31: 30 | B31: 496 | C31: CFC | D31: 1 Motor ( ) 2 Dewasa | E31: 4,5,11,12,18,19,25,26 oktober 2025 | F31: Loading Barang Promo | G31: 06,00 s/d 07,30 WIB.
A32: 31 | B32: 497 | C32: PT. AMAN FOOD INDUSTRI Teh Ngaso / Teh Semesta | D32: 1 Mobil ( ),1 Motor( ) 3 Dewasa | E32: 5, 12, 19 26 Oktober 2025 | F32: Loading Barang Promo | G32: 06,00 s/d 07,30 WIB.
A33: 32 | B33: 498 | C33: Temu kangen pendawa 3 | D33: 1 Mobil B 1874 PKA | E33: 45935 | F33: Loading Barang ke Pendopo 1 DI TSA | G33: 06,00 s/d 07,30 WIB.
A34: 33 | B34: 499 | C34: Oishi | D34: 1 mobil 4 Dewasa | E34: 4,5,11,12,18,19,25,26 Oktober 2025 | F34: loading barang promo | G34: 06,00 s/d 07,30 WIB.
A35: 34 | B35: 500 | C35: Dua Kelici | D35: 1 monbil 5 Dewasa | E35: 5, 12 Oktober 2025 | F35: loading barang promo | G35: maksimal 06 :00 WIB
A36: 35 | B36: 501 | C36: Two Thubmbs | D36: 2 mobil 2 dewaa | E36: 4.5.11.12 Oktober 2025 | F36: loading promo | G36: maksimal 06 :00 WIB
A37: 36 | B37: 502 | C37: Helmi | D37: 1 mobil (B 2352 BIL) | E37: 45934 | F37: loading barang lapangan beringin | G37: 06,00 s/d 07,30 WIB.
A38: 37 | B38: 503 | C38: Ibu Reni Aprilia | D38: 1 mobil (B 1784 WYG) | E38: 45935 | F38: Loading Barang ke- TSA 3 | G38: 07,00 s/d 07,30 WIB.
A39: 38 | B39: 504 | C39: wiwi kelurahan johar baru | D39: 1 Mobil (B 2423 TOH) | E39: 45942 | F39: loading barang ke TSA 2 | G39: 07,00 s/d 07,30 WIB.
A40: 39 | B40: 505 | C40: Ichitan | D40: 1 mobil 3 dewasa | E40: 45935 | F40: loading promo | G40: maksimal 06 :00 WIB
...

Sheet Dispensasi
C1: PEMERINTAH PROVINSI DAERAH KHUSUS IBU KOTA JAKARTA
C2: DINAS PERTAMANAN DAN HUTAN KOTA
C3: UNIT PENGELOLA TAMAN MARGASATWA RAGUNAN
C4: Jalan harsono RM. No. 1 Ragunan, Telp (021) 7820015 fax. (021) 7805280
C5: website : www.ragunanzoo.jakarta.go.id e-mail : ragunanzoo@jakarta.go.id
C6: JAKARTA
I7: Kode Pos : 12550
A8: DISPENSASI
E9: NOMOR : | G9: =VLOOKUP('2026'!H1, '2026'!A2:F999, 2) -> 434
A11: Kepala Unit Pengelola Taman Margasatwa Ragunan Provinsi DKI Jakarta memberikan ijin kepada :
A12: Nama Rombongan | C12: : | D12: =VLOOKUP('2026'!H1, '2026'!A2:H1000,3) -> WKRI Ranting 4
A13: Tanggal Kunjungan | C13: : | D13: =VLOOKUP('2026'!H1, '2026'!A2:H1000,5) -> 8 aguistus 2026
A14: Keperluan | C14: : | D14: =VLOOKUP('2026'!H1, '2026'!A2:H1000,6) -> loading barang LAP TSIK 1
A15: Nomor Kendaraan | C15: : | D15: =VLOOKUP('2026'!H1, '2026'!A2:H1000,4) -> B 266 ADV
B17: Ketentuan :
A18: 1 | B18: Setelah selesai menurunkan barang, kendaraan kembali ke tempat parkir TMR dan tidak diperkenankan parkir ditempat acara ataupun berkeliling didalam kawasan TMR.
A19: 2 | B19: Setiap pengantar barang wajib membayar tarif masuk berikut kendaraannya.
A20: 3 | B20: Jadwal loading dari hari selasa s/d Minggu, | F20: =VLOOKUP('2026'!H1, '2026'!$A:$G, 7) -> 07,00 s/d 08,00 WIB.
A22: Demikian Dispensasi ini diberikan untuk digunakan sebagai mestinya.
H26: ="Jakarta, "& TEXT(TODAY(),"dddd dd mmmm yyyy" ) -> Jakarta, Kamis 06 Agustus 2026
H28: Kepala Unit Pengelola
H29: Taman Margasatwa Ragunan
H30: Dinas Pertamanan dan Hutan Kota
H31: Provinsi DKI Jakarta

Sheet 2026
A1: No | B1: Nomor Surat | C1: Nama Rombongan / Instansi | D1: NOPOL | E1: Tanggal Kunjungan | F1: Keperluan | G1: Jam Loading | H1: 434
A2: 1 | B2: 1 | C2: Two thumbs Ice cream | D2: 2 Dewasa 2 Mobil ( ) ( ) | E2: 8,9,10,11,17,18, 24 januari 2026 | F2: Loading Barang Promo | G2: maksimal 06 :00 WIB | H2: Dispensasi
A3: 2 | B3: 2 | C3: koperasi guru jatiasih | D3: 3 mobil ( B 2107 BRJ ) ( B 2723 YC ) ( B 2177 KYC ) | E3: 46039 | F3: loading barang gedung serbaguna | G3: 06,00 s/d 07,30 WIB.
A4: 3 | B4: 3 | C4: ibu sulistiawati | D4: 1 mobil (B 1986 TVB) | E4: 46032 | F4: loading barang pendopo TSA 3 | G4: 06,00 s/d 07,30 WIB. | H4: https://docs.google.com/spreadsheets/d/1GIYP3gKlwKD1FjOm9J1bBxcXXS3yi7xxxQRVqMkhHXI/edit?gid=677168732#gid=677168732
A5: 4 | B5: 4 | C5: PT. DOMINOS | D5: 2 Dewasa 1 Mobil ( ) 1 Motor( ) | E5: 10, 11, 12, 17, 18, 24, 25, 31 Januari dan 1, 7 Februari 2026 | F5: Loading Barang Promo | G5: maksimal 06 :00 WIB
A6: 5 | B6: 5 | C6: PT. Pioneerindo Gourmet Internasional tbk call donat | D6: 2 Dewasa 1 Mobil ( ) 1 Motor ( ) | E6: 10,11,17,18,24,25,31 Januari dan 01 Februari 2026 | F6: Loading Barang Promo | G6: maksimal 06 :00 WIB
A7: 6 | B7: 6 | C7: PT PIONEERINDO GOURMET INT | D7: 2 Dewasa 1 Mobil ( ) | E7: 10,11,17,18,24,25,31 Januari dan 01 Februari 2026 | F7: Loading Barang Promo | G7: maksimal 06 :00 WIB
A8: 7 | B8: 7 | C8: kartadinama | D8: 1 mobil B 1933 SRQ | E8: 46033 | F8: loading barang | G8: 06,00 s/d 07,30 WIB.
A9: 8 | B9: 8 | C9: BSI | D9: 1 Mobil ( B 1894 DYF ) | E9: 46032 | F9: Loading Barang Pendopo TSA 3 | G9: 07,00 s/d 07,30 WIB.
A10: 9 | B10: 9 | C10: Jus Antara | D10: 3 Dewasa 1 Mobil | E10: 46040 | F10: Loading barang promo | G10: maksimal 06 :00 WIB
A11: 10 | B11: 10 | C11: Two thumbs ice cream | D11: 2 Dewasa 2 Mobil ( ) ( ) | E11: 16 dan 25 Januari 2026 | F11: Loading barang promo | G11: maksimal 06 :00 WIB
A12: 11 | B12: 11 | C12: SDTQ Imam Syafi'i | D12: 2 mobil ( B 2914 SRD ) ( B 8322 BW ) | E12: 8 febuari 2026 | F12: loading barang aula serbaguna | G12: 06,00 s/d 07,30 WIB.
A13: 12 | B13: 12 | C13: OISHI | D13: 4 Dewasa 1 Mobil ( ) | E13: 16,17,18,25,31, Januari 2026 | F13: Loading Barang Promo | G13: maksimal 06 :00 WIB
A14: 13 | B14: 13 | C14: Biller Pane | D14: 1 mobil (B 1073 FYZ ) | E14: 46038 | F14: loading barang | G14: 07,00 s/d 07,30 WIB.
A15: 14 | B15: 14 | C15: DHORID | D15: 1 mobil (B 1210 WN) | E15: 18, 25 JANUARI DAN 1, 8 FEBRUARI 2026 | F15: LOADING BARANG PROMO | G15: maksimal 06 :00 WIB
A16: 15 | B16: 15 | C16: Arisan Mak Ijah | D16: 1 Mobil ( B 9498 EUC ) | E16: 46040 | F16: Loading Barang Pendopo TSA 4 | G16: 07,00 s/d 07,30 WIB.
A17: 16 | B17: 16 | C17: IGTKI KECAMATAN JAGAKARSA | D17: 1 MOBIL ( F 1766 LA ) | E17: 46043 | F17: Loading barang | G17: 14,00 s/d 15,00 WIB.
A18: 17 | B18: 17 | C18: IGTKI KECAMATAN JAGAKARSA | D18: 4 Kendaraan TAXI ONLINE | E18: 46044 | F18: Loading Barang ke Gazebo | G18: 07,00 s/d 07,30 WIB.
A19: 18 | B19: 18 | C19: CV.Karya Insan Mandiri | D19: 1 mobil ( D 8483 WI ) | E19: 46047 | F19: loading barang aula serbaguna | G19: 06,00 s/d 07,30 WIB.
A20: 19 | B20: 19 | C20: ULS Jabodetabek ( Maman Keswan ) | D20: 3 mobil ( B 2048 KNI ) ( B 1133 KI ) ( B 2344 PBS ) | E20: 46046 | F20: Loading Barang | G20: 06,00 s/d 07,30 WIB.
A21: 20 | B21: 20 | C21: Taro FKS Food Sejahtera | D21: 1 Mobil, 5 orang | E21: 24,25,31 Januari, 01 Februari 2026 | F21: Loading Barang | G21: 06,00 s/d 07,30 WIB.
A22: 21 | B22: 21 | C22: IBU YAYUK | D22: 2 Mobil B 2898 SYF dan ( ) | E22: 46046 | F22: Loading Barang ke Aula Serbaguna | G22: 06,00 s/d 07,30 WIB.
A23: 22 | B23: 22 | C23: Ikapureka | D23: 1 Mobil ( B 219 RRF ) | E23: 46047 | F23: Loading Barang Gazebo | G23: 06,00 s/d 07,30 WIB.
A24: 23 | B24: 23 | C24: Maria ( Pendopo 4 ) | D24: 1 Mobil ( B 1541 URB ) | E24: 46047 | F24: Loading Barang | G24: 06,00 s/d 07,30 WIB.
A25: 24 | B25: 24 | C25: Ibu iin indarwati | D25: 1 Mobil ( B 1293 SRV ) | E25: 46054 | F25: Loading Barang Gazebo | G25: 06,00 s/d 07,30 WIB.
A26: 25 | B26: 25 | C26: Bani Hamim | D26: 1 Mobil ( B 1794 KYT ) | E26: 46054 | F26: Loading Barang LAP TIMUR INF 1 | G26: 06,00 s/d 07,30 WIB.
A27: 26 | B27: 26 | C27: Domino's Pizza | D27: 2 Dewasa 1 Mobil ( ) 1 Motor( ) | E27: 8, 14, 15 Februari dan 20, 21, 22, 23, 24 Maret 2026 | F27: Loading barang promo | G27: maksimal 06 :00 WIB
A28: 27 | B28: 27 | C28: PT. Sumber Karya Pakarindo | D28: 4 Orang, 1 Mobil ( ) 1 Motor ( ) | E28: 1,7,8,14,15 februari dan 22,23,24,25,26,27,28,29 maret 2026 | F28: Loading Barang | G28: 06,00 s/d 07,30 WIB.
A29: 28 | B29: 28 | C29: NEEDS | D29: 3 orang , 1 Mobil ( ) | E29: 31 januari dan 1,7,8 febuari | F29: Loading Barang | G29: maksimal 06 :00 WIB
A30: 29 | B30: 29 | C30: Two thumbs ice cream | D30: 2 Dewasa 2 Mobil ( ) ( ) | E30: 31 Januari 2026 dan 1,7,8 Febuari 2026 | F30: Loading Barang Promo | G30: maksimal 06 :00 WIB
A31: 30 | B31: 30 | C31: TPA AR Rahmah | D31: 1 mobil (B 2461UKB), 2 dewasa | E31: 46053 | F31: Loading Barang | G31: 07,00 s/d 07,30 WIB.
A32: 31 | B32: 31 | C32: Bu Santi | D32: 1 Mobil ( B 1532 DZG ) | E32: 46023 | F32: Loading Barang | G32: 07,00 s/d 07,30 WIB.
A33: 32 | B33: 32 | C33: TK Assalam kebagusan | D33: 1 Mobil ( B 1477 SRY) | E33: 46058 | F33: Loading Barang Pendopo TSA 2 dan 3 | G33: 07,00 s/d 07,30 WIB.
A34: 33 | B34: 33 | C34: PT. PIONEERINDO GOURMET | D34: 1 Motor ( ) 2 dewasa | E34: 7,8,14,15,16,17 febuari 2026 | F34: loading barang | G34: maksimal 06 :00 WIB
A35: 34 | B35: 34 | C35: PT MARGA NUSANTARA JAYA | D35: 5 Dewasa 1 Mobil ( ) | E35: 46061 | F35: loading barang aula serbaguna | G35: maksimal 06 :00 WIB
A36: 35 | B36: 35 | C36: Korpri Bareskrim Mabes Polri | D36: 1 MOBIL ( B. 2606 SIV ) | E36: 7 Febuari 2026 | F36: loading barang aula serbaguna | G36: 06,00 s/d 07,30 WIB.
A37: 36 | B37: 36 | C37: Korpri Bareskrim Mabes Polri | D37: 1 MOBIL ( B. 168.WUK ) | E37: 7 Febuari 2026 | F37: loading barang aula serbaguna | G37: maksimal 06 :00 WIB
A38: 37 | B38: 37 | C38: Korpri Bareskrim Mabes Polri | D38: 1 MOBIL ( Taksi online ) | E38: 7 Febuari 2026 | F38: loading barang aula serbaguna | G38: maksimal 06 :00 WIB
A39: 38 | B39: 38 | C39: Korpri Bareskrim Mabes Polri | D39: 1 MOBIL ( Taksi online ) | E39: 7 Febuari 2026 | F39: loading barang aula serbaguna | G39: maksimal 06 :00 WIB
A40: 39 | B40: 39 | C40: STHQ | D40: 1 MOBIL ( B 2396 SIK ) | E40: 5 FEBUARI 2026 | F40: LOADING BARANG LAP TIMUR INF 1 | G40: 07,00 s/d 07,30 WIB.
...

Sheet Sheet12
A1: AGUSTUS | B1: TANGGAL | C1: NO | D1: TGL | E1: BLN | F1: KET | G1: THN | H1: JUMLAH KARTU/PCS | I1: JUMLAH KARTU/PCS 2
A2: =TEXT(C2,"000")&"/"&D2&"/"&E2&"/"&F2&"/"&G2 -> 211/2/9/SUKJ/2025 | B2: 45902 | C2: 211 | D2: 2 | E2: 9 | F2: SUKJ | G2: 2025 | H2: 186 | I2: 36
A3: =TEXT(C3,"000")&"/"&D3&"/"&E3&"/"&F3&"/"&G3 -> 212/3/9/SUKJ/2025 | B3: 45903 | C3: 212 | D3: 3 | E3: 9 | F3: SUKJ | G3: 2025 | H3: 150 | I3: 36
A4: =TEXT(C4,"000")&"/"&D4&"/"&E4&"/"&F4&"/"&G4 -> 213/4/9/SUKJ/2025 | B4: 45904 | C4: 213 | D4: 4 | E4: 9 | F4: SUKJ | G4: 2025 | H4: 161 | I4: 28
A5: =TEXT(C5,"000")&"/"&D5&"/"&E5&"/"&F5&"/"&G5 -> 214/5/9/SUKJ/2025 | B5: 45905 | C5: 214 | D5: 5 | E5: 9 | F5: SUKJ | G5: 2025
A6: =TEXT(C6,"000")&"/"&D6&"/"&E6&"/"&F6&"/"&G6 -> 215/6/9/SUKJ/2025 | B6: 45906 | C6: 215 | D6: 6 | E6: 9 | F6: SUKJ | G6: 2025 | H6: 910 | I6: 226
A7: =TEXT(C7,"000")&"/"&D7&"/"&E7&"/"&F7&"/"&G7 -> 216/7/9/SUKJ/2025 | B7: 45907 | C7: 216 | D7: 7 | E7: 9 | F7: SUKJ | G7: 2025 | H7: 1758 | I7: 458 | L7: ="Hari/Tanggal : "& TEXT(TODAY(),"dddd dd mmmm" ) -> Hari/Tanggal : Kamis 06 Agustus
A8: =TEXT(C8,"000")&"/"&D8&"/"&E8&"/"&F8&"/"&G8 -> 217/9/9/SUKJ/2025 | B8: 45909 | C8: 217 | D8: 9 | E8: 9 | F8: SUKJ | G8: 2025 | H8: 162 | I8: 34
A9: =TEXT(C9,"000")&"/"&D9&"/"&E9&"/"&F9&"/"&G9 -> 218/10/9/SUKJ/2025 | B9: 45910 | C9: 218 | D9: 10 | E9: 9 | F9: SUKJ | G9: 2025 | H9: 213 | I9: 30
A10: =TEXT(C10,"000")&"/"&D10&"/"&E10&"/"&F10&"/"&G10 -> 219/11/9/SUKJ/2025 | B10: 45911 | C10: 219 | D10: 11 | E10: 9 | F10: SUKJ | G10: 2025 | H10: 187 | I10: 33
A11: =TEXT(C11,"000")&"/"&D11&"/"&E11&"/"&F11&"/"&G11 -> 220/12/9/SUKJ/2025 | B11: 45912 | C11: 220 | D11: 12 | E11: 9 | F11: SUKJ | G11: 2025 | H11: 125 | I11: 30
A12: =TEXT(C12,"000")&"/"&D12&"/"&E12&"/"&F12&"/"&G12 -> 221/13/9/SUKJ/2025 | B12: 45913 | C12: 221 | D12: 13 | E12: 9 | F12: SUKJ | G12: 2025 | H12: 858 | I12: 209
A13: =TEXT(C13,"000")&"/"&D13&"/"&E13&"/"&F13&"/"&G13 -> 222/14/9/SUKJ/2025 | B13: 45914 | C13: 222 | D13: 14 | E13: 9 | F13: SUKJ | G13: 2025 | H13: 1658 | I13: 453
A14: =TEXT(C14,"000")&"/"&D14&"/"&E14&"/"&F14&"/"&G14 -> 223/16/9/SUKJ/2025 | B14: 45916 | C14: 223 | D14: 16 | E14: 9 | F14: SUKJ | G14: 2025 | H14: 132 | I14: 19
A15: =TEXT(C15,"000")&"/"&D15&"/"&E15&"/"&F15&"/"&G15 -> 224/17/9/SUKJ/2025 | B15: 45917 | C15: 224 | D15: 17 | E15: 9 | F15: SUKJ | G15: 2025 | H15: 200 | I15: 36
A16: =TEXT(C16,"000")&"/"&D16&"/"&E16&"/"&F16&"/"&G16 -> 225/18/9/SUKJ/2025 | B16: 45918 | C16: 225 | D16: 18 | E16: 9 | F16: SUKJ | G16: 2025 | H16: 143 | I16: 30
A17: =TEXT(C17,"000")&"/"&D17&"/"&E17&"/"&F17&"/"&G17 -> 226/19/9/SUKJ/2025 | B17: 45919 | C17: 226 | D17: 19 | E17: 9 | F17: SUKJ | G17: 2025 | H17: 160 | I17: 23
A18: =TEXT(C18,"000")&"/"&D18&"/"&E18&"/"&F18&"/"&G18 -> 227/20/9/SUKJ/2025 | B18: 45920 | C18: 227 | D18: 20 | E18: 9 | F18: SUKJ | G18: 2025 | H18: 756 | I18: 172
A19: =TEXT(C19,"000")&"/"&D19&"/"&E19&"/"&F19&"/"&G19 -> 228/21/9/SUKJ/2025 | B19: 45921 | C19: 228 | D19: 21 | E19: 9 | F19: SUKJ | G19: 2025 | H19: 1494 | I19: 418
... A22: =TEXT(C22,"000")&"/"&D22&"/"&E22&"/"&F22&"/"&G22 -> 231/25/9/SUKJ/2025 | B22: 45925 | C22: 231 | D22: 25 | E22: 9 | F22: SUKJ | G22: 2025 | H22: 148 | I22: 36
A23: =TEXT(C23,"000")&"/"&D23&"/"&E23&"/"&F23&"/"&G23 -> 232/26/9/SUKJ/2025 | B23: 45926 | C23: 232 | D23: 26 | E23: 9 | F23: SUKJ | G23: 2025
A24: =TEXT(C24,"000")&"/"&D24&"/"&E24&"/"&F24&"/"&G24 -> 233/27/9/SUKJ/2025 | B24: 45927 | C24: 233 | D24: 27 | E24: 9 | F24: SUKJ | G24: 2025
A25: =TEXT(C25,"000")&"/"&D25&"/"&E25&"/"&F25&"/"&G25 -> 234/28/9/SUKJ/2025 | B25: 45928 | C25: 234 | D25: 28 | E25: 9 | F25: SUKJ | G25: 2025
A26: =TEXT(C26,"000")&"/"&D26&"/"&E26&"/"&F26&"/"&G26 -> 235/30/9/SUKJ/2025 | B26: 45930 | C26: 235 | D26: 30 | E26: 9 | F26: SUKJ | G26: 2025

Sheet Sheet15

Sheet Sheet3
E2: DATA DISPENSASI
A3: Agung Puji Saputra | B3: 45901 | C3: Utara 1
A4: Ahmad Maulana | B4: 45902 | C4: Utara 2
A5: Aldi Priadi Ekapaksi | B5: 45903 | C5: Utara 3
A6: Amanda Luthfia Ramadhani | B6: 45904 | C6: Tol Utara
A7: Amanda Sabila | B7: 45905 | C7: Barat Kendaraan
A8: Arif Nurdiansah | B8: 45906
A9: Eka Priyatiningsih | B9: 45907
A10: Erfan | B10: 45908
A11: Ernawati Yuliastiningsih | B11: 45909
A12: Ervi Irawati | B12: 45910
A13: Febria Shafira | B13: 45911
A14: Feiruz | B14: 45912
A15: Fildzah Shabrina | B15: 45913
A16: Firda Anjanie | B16: 45914
A17: Herdi Nofiandi | B17: 45915
A18: Ilham Setiyono | B18: 45916
A19: Irma Khotimah | B19: 45917
... A32: Sahara Firyal Humaira | B32: 45930
A33: Sarifudin
A34: Siska Rahmawati
A35: Uci Anggraini
A36: Widyo Siswantoro
A37: Yusuf Safii
